Workbook

Sheet 1_Svodka
A1: Калькулятор компоновки одной овчарни по НТП-АПК
A3: Входные параметры — желтые поля задаются вручную | F3: Настройка способа учета дверей
A4: Порода / направление | B4: каракульское и мясо-сальное | C4: фиксировано | D4: Колонка НТП-АПК, табл. 9 | F4: Режим расчета дверей | G4: 2 — фиксированное число по сторонам | H4: ручной ввод | I4: 1 — число секций × дверей на секцию; 2 — фиксированное число отдельно слева и справа
A5: Расчет | B5: племенное поголовье | C5: фиксировано | D5: К нормам площади применяется надбавка(указывается в строке 12) | F5: Фиксированное число дверей слева, шт. | G5: 3 | H5: ручной ввод | I5: Используется только в режиме 2
A6: Лимит площади одного здания, м² | B6: 1500 | C6: ручной ввод | D6: Проектное ограничение по метражу | F6: Фиксированное число дверей справа, шт. | G6: 5 | H6: ручной ввод | I6: Используется только в режиме 2
A7: Длина овчарни L, м | B7: 140 | C7: ручной ввод | D7: Это же и длина кормовой линии до вычета дверей | F7: Расчет по секциям слева, шт. | G7: ='2_Komponovka'!J16 -> 15 | H7: автоматически | I7: Справочно: сумма дверей по группам и секциям
A8: Ширина центрального кормового проезда, м | B8: 2.6 | C8: ручной ввод | D8: Задается по применяемой технике(предаврительно ширина К13 2,6 с запасом) | F8: Расчет по секциям справа, шт. | G8: ='2_Komponovka'!K16 -> 15 | H8: автоматически | I8: Справочно: сумма дверей по группам и секциям
A9: Учитывать техпроходы вдоль наружных стен? | B9: Нет | C9: ручной ввод | D9: По одному продольному проходу с каждой стороны | F9: Используется в расчете слева, шт. | G9: =IF(G4="2 — фиксированное число по сторонам",G5,G7) -> 3 | H9: автоматически | I9: Итоговое число дверей по выбранному режиму
A10: Ширина одного техпрохода вдоль стены, м | B10: 1 | C10: ручной ввод | D10: При «0» не участвует в расчете | F10: Используется в расчете справа, шт. | G10: =IF(G4="2 — фиксированное число по сторонам",G6,G8) -> 5 | H10: автоматически | I10: Итоговое число дверей по выбранному режиму
A11: Ширина зоны содержания овец с каждой стороны, м | B11: 4 | C11: ручной ввод | D11: Одинаковая ширина слева и справа (обсуждалось 4 метра оптимальная ширина)
A12: Надбавка площади для племенных животных | B12: 0.2 | C12: ручной ввод | D12: До 20% по табл. 9, прим. 1
A13: Дверей на одну секцию, шт. | B13: 1 | C13: ручной ввод | D13: Без учета пожарных требований(по требованиям там идет 1 дверь на 100 голов РД-АПК 1.10.03.02-12) - лучше проверить отдельно
A14: Ширина одной двери, м | B14: 1.2 | C14: ручной ввод | D14: Все двери выходят в центральный кормовой проход(то есть фронт уменьшается)
A15: Режим кормления откормочного поголовья | B15: Нормированное кормление (1 голова на место) | C15: ручной ввод | D15: По п. 7.3 НТП-АПК (только для откормочного молодняка и взрослых)
A17: Расчетные показатели одной овчарни
A18: Максимальная ширина здания по лимиту, м | B18: =B6/B7 -> 10.714286 | C18: лимит / длина
A19: Расчетная общая ширина здания, м | B19: =B8+2*B11+2*IF(B9="Да",B10,0) -> 10.6 | C19: центр + 2 зоны + 2 техпрохода
A20: Расчетная площадь здания, м² | B20: =B7*B19 -> 1484 | C20: длина × расчетная ширина
A21: Запас (+) / превышение (−) лимита, м² | B21: =B6-B20 -> 16 | C21: лимит − расчетная площадь
A22: Площадь центрального прохода, м² | B22: =B7*B8 -> 364 | C22: L × ширина центра
A23: Площадь двух техпроходов вдоль стен, м² | B23: =2*B7*IF(B9="Да",B10,0) -> 0 | C23: только продольные полосы
A24: Доступная площадь содержания слева, м² | B24: =B7*B11 -> 560 | C24: L × ширина зоны слева
A25: Занятая площадь слева, м² | B25: ='2_Komponovka'!D16 -> 540 | C25: сумма групп слева
A26: Остаток площади слева, м² | B26: =B24-B25 -> 20 | C26: доступно − занято
A27: Доступная площадь содержания справа, м² | B27: =B7*B11 -> 560 | C27: L × ширина зоны справа
A28: Занятая площадь справа, м² | B28: ='2_Komponovka'!E16 -> 540 | C28: сумма групп справа
A29: Остаток площади справа, м² | B29: =B27-B28 -> 20 | C29: доступно − занято
A30: Используемое число дверей слева, шт. | B30: =G9 -> 3 | C30: по выбранному режиму
A31: Вычет из кормовой линии слева, м | B31: =B30*B14 -> 3.6 | C31: двери × ширина двери
A32: Полезный фронт кормления слева, м | B32: =MAX(0,B7-B31) -> 136.4 | C32: L − дверные проемы
A33: Требуемый фронт кормления слева, м | B33: ='2_Komponovka'!F16 -> 135 | C33: сумма по группам
A34: Остаток фронта слева, м | B34: =B32-B33 -> 1.4 | C34: полезный − требуемый
A35: Используемое число дверей справа, шт. | B35: =G10 -> 5 | C35: по выбранному режиму
A36: Вычет из кормовой линии справа, м | B36: =B35*B14 -> 6 | C36: двери × ширина двери
A37: Полезный фронт кормления справа, м | B37: =MAX(0,B7-B36) -> 134 | C37: L − дверные проемы
A38: Требуемый фронт кормления справа, м | B38: ='2_Komponovka'!G16 -> 135 | C38: сумма по группам
A39: Остаток фронта справа, м | B39: =B37-B38 -> -1 | C39: полезный − требуемый
A40: Итоговый статус | B40: =IF(AND(B21>=0,B26>=0,B29>=0,B34>=0,B39>=0),"ПРОХОДИТ","НЕ ПРОХОДИТ") -> НЕ ПРОХОДИТ | C40: площадь здания + обе стороны + оба фронта
A45: Группа | B45: Голов слева | C45: Голов справа | D45: Всего | E45: Площадь слева, м² | F45: Площадь справа, м² | G45: Фронт слева, м | H45: Фронт справа, м | I45: Двери Л / П
A46: ='2_Komponovka'!A2 -> Бараны-производители | B46: ='2_Komponovka'!B2 -> 0 | C46: ='2_Komponovka'!C2 -> 0 | D46: ='2_Komponovka'!B2+'2_Komponovka'!C2 -> 0 | E46: ='2_Komponovka'!D2 -> 0 | F46: ='2_Komponovka'!E2 -> 0 | G46: ='2_Komponovka'!F2 -> 0 | H46: ='2_Komponovka'!G2 -> 0 | I46: =IF($G$4="2 — фиксированное число по сторонам","—",'2_Komponovka'!J2&" / "&'2_Komponovka'!K2) -> —
...

Sheet 2_Komponovka
A1: Группа животных | B1: Голов слева | C1: Голов справа | D1: Площадь слева, м² | E1: Площадь справа, м² | F1: Треб. фронт слева, м | G1: Треб. фронт справа, м | H1: Секций слева | I1: Секций справа | J1: Дверей по секциям слева | K1: Дверей по секциям справа | L1: Комментарий | M1: Плем. норма, м²/гол. | N1: Фронт, м/гол. | O1: Макс. секция, гол.
A2: Бараны-производители | B2: 0 | C2: 0 | D2: =B2*M2 -> 0 | E2: =C2*M2 -> 0 | F2: =B2*N2 -> 0 | G2: =C2*N2 -> 0 | H2: =IF(B2>0,CEILING(B2/O2,1),0) -> 0 | I2: =IF(C2>0,CEILING(C2/O2,1),0) -> 0 | J2: =H2*'1_Svodka'!$B$13 -> 0 | K2: =I2*'1_Svodka'!$B$13 -> 0 | L2: =IF(B2+C2=0,"",H2&" секц. слева / "&I2&" справа; "&J2&" дверей слева / "&K2&" справа") | M2: ='3_Normativy'!C2 -> 2.4 | N2: ='3_Normativy'!F2 -> 0.5 | O2: ='3_Normativy'!G2 -> 25
A3: Бараны-пробники | B3: 0 | C3: 0 | D3: =B3*M3 -> 0 | E3: =C3*M3 -> 0 | F3: =B3*N3 -> 0 | G3: =C3*N3 -> 0 | H3: =IF(B3>0,CEILING(B3/O3,1),0) -> 0 | I3: =IF(C3>0,CEILING(C3/O3,1),0) -> 0 | J3: =H3*'1_Svodka'!$B$13 -> 0 | K3: =I3*'1_Svodka'!$B$13 -> 0 | L3: =IF(B3+C3=0,"",H3&" секц. слева / "&I3&" справа; "&J3&" дверей слева / "&K3&" справа") | M3: ='3_Normativy'!C3 -> 2.16 | N3: ='3_Normativy'!F3 -> 0.5 | O3: ='3_Normativy'!G3 -> 50
A4: Матки холостые | B4: 0 | C4: 0 | D4: =B4*M4 -> 0 | E4: =C4*M4 -> 0 | F4: =B4*N4 -> 0 | G4: =C4*N4 -> 0 | H4: =IF(B4>0,CEILING(B4/O4,1),0) -> 0 | I4: =IF(C4>0,CEILING(C4/O4,1),0) -> 0 | J4: =H4*'1_Svodka'!$B$13 -> 0 | K4: =I4*'1_Svodka'!$B$13 -> 0 | L4: =IF(B4+C4=0,"",H4&" секц. слева / "&I4&" справа; "&J4&" дверей слева / "&K4&" справа") | M4: ='3_Normativy'!C4 -> 0.84 | N4: ='3_Normativy'!F4 -> 0.3 | O4: ='3_Normativy'!G4 -> 250
A5: Матки суягные | B5: 0 | C5: 0 | D5: =B5*M5 -> 0 | E5: =C5*M5 -> 0 | F5: =B5*N5 -> 0 | G5: =C5*N5 -> 0 | H5: =IF(B5>0,CEILING(B5/O5,1),0) -> 0 | I5: =IF(C5>0,CEILING(C5/O5,1),0) -> 0 | J5: =H5*'1_Svodka'!$B$13 -> 0 | K5: =I5*'1_Svodka'!$B$13 -> 0 | L5: =IF(B5+C5=0,"",H5&" секц. слева / "&I5&" справа; "&J5&" дверей слева / "&K5&" справа") | M5: ='3_Normativy'!C5 -> 1.2 | N5: ='3_Normativy'!F5 -> 0.3 | O5: ='3_Normativy'!G5 -> 250
A6: Матки подсосные с ягнятами до 10 дней | B6: 300 | C6: 300 | D6: =B6*M6 -> 432 | E6: =C6*M6 -> 432 | F6: =B6*N6 -> 90 | G6: =C6*N6 -> 90 | H6: =IF(B6>0,CEILING(B6/O6,1),0) -> 3 | I6: =IF(C6>0,CEILING(C6/O6,1),0) -> 3 | J6: =H6*'1_Svodka'!$B$13 -> 3 | K6: =I6*'1_Svodka'!$B$13 -> 3 | L6: =IF(B6+C6=0,"",H6&" секц. слева / "&I6&" справа; "&J6&" дверей слева / "&K6&" справа") -> 3 секц. слева / 3 справа; 3 дверей слева / 3 справа | M6: ='3_Normativy'!C6 -> 1.44 | N6: ='3_Normativy'!F6 -> 0.3 | O6: ='3_Normativy'!G6 -> 120
A7: Матки подсосные старше 10 дней, зимнее ягнение | B7: 0 | C7: 0 | D7: =B7*M7 -> 0 | E7: =C7*M7 -> 0 | F7: =B7*N7 -> 0 | G7: =C7*N7 -> 0 | H7: =IF(B7>0,CEILING(B7/O7,1),0) -> 0 | I7: =IF(C7>0,CEILING(C7/O7,1),0) -> 0 | J7: =H7*'1_Svodka'!$B$13 -> 0 | K7: =I7*'1_Svodka'!$B$13 -> 0 | L7: =IF(B7+C7=0,"",H7&" секц. слева / "&I7&" справа; "&J7&" дверей слева / "&K7&" справа") | M7: ='3_Normativy'!C7 -> 1.44 | N7: ='3_Normativy'!F7 -> 0.3 | O7: ='3_Normativy'!G7 -> 120
A8: Матки подсосные старше 10 дней, весеннее ягнение | B8: 0 | C8: 0 | D8: =B8*M8 -> 0 | E8: =C8*M8 -> 0 | F8: =B8*N8 -> 0 | G8: =C8*N8 -> 0 | H8: =IF(B8>0,CEILING(B8/O8,1),0) -> 0 | I8: =IF(C8>0,CEILING(C8/O8,1),0) -> 0 | J8: =H8*'1_Svodka'!$B$13 -> 0 | K8: =I8*'1_Svodka'!$B$13 -> 0 | L8: =IF(B8+C8=0,"",H8&" секц. слева / "&I8&" справа; "&J8&" дверей слева / "&K8&" справа") | M8: ='3_Normativy'!C8 -> 1.2 | N8: ='3_Normativy'!F8 -> 0.3 | O8: ='3_Normativy'!G8 -> 120
A9: Ремонтный молодняк | B9: 0 | C9: 0 | D9: =B9*M9 -> 0 | E9: =C9*M9 -> 0 | F9: =B9*N9 -> 0 | G9: =C9*N9 -> 0 | H9: =IF(B9>0,CEILING(B9/O9,1),0) -> 0 | I9: =IF(C9>0,CEILING(C9/O9,1),0) -> 0 | J9: =H9*'1_Svodka'!$B$13 -> 0 | K9: =I9*'1_Svodka'!$B$13 -> 0 | L9: =IF(B9+C9=0,"",H9&" секц. слева / "&I9&" справа; "&J9&" дверей слева / "&K9&" справа") | M9: ='3_Normativy'!C9 -> 0.84 | N9: ='3_Normativy'!F9 -> 0.3 | O9: ='3_Normativy'!G9 -> 250
A10: Ягнята до 45 дней | B10: 300 | C10: 300 | D10: =B10*M10 -> 108 | E10: =C10*M10 -> 108 | F10: =B10*N10 -> 45 | G10: =C10*N10 -> 45 | H10: =IF(B10>0,CEILING(B10/O10,1),0) -> 12 | I10: =IF(C10>0,CEILING(C10/O10,1),0) -> 12 | J10: =H10*'1_Svodka'!$B$13 -> 12 | K10: =I10*'1_Svodka'!$B$13 -> 12 | L10: =IF(B10+C10=0,"",H10&" секц. слева / "&I10&" справа; "&J10&" дверей слева / "&K10&" справа") -> 12 секц. слева / 12 справа; 12 дверей слева / 12 справа | M10: ='3_Normativy'!C10 -> 0.36 | N10: ='3_Normativy'!F10 -> 0.15 | O10: ='3_Normativy'!G10 -> 25
A11: Ягнята старше 45 дней до 4 месяцев | B11: 0 | C11: 0 | D11: =B11*M11 -> 0 | E11: =C11*M11 -> 0 | F11: =B11*N11 -> 0 | G11: =C11*N11 -> 0 | H11: =IF(B11>0,CEILING(B11/O11,1),0) -> 0 | I11: =IF(C11>0,CEILING(C11/O11,1),0) -> 0 | J11: =H11*'1_Svodka'!$B$13 -> 0 | K11: =I11*'1_Svodka'!$B$13 -> 0 | L11: =IF(B11+C11=0,"",H11&" секц. слева / "&I11&" справа; "&J11&" дверей слева / "&K11&" справа") | M11: ='3_Normativy'!C11 -> 0.48 | N11: ='3_Normativy'!F11 -> 0.2 | O11: ='3_Normativy'!G11 -> 50
A12: Откормочное поголовье взрослое | B12: 0 | C12: 0 | D12: =B12*M12 -> 0 | E12: =C12*M12 -> 0 | F12: =B12*N12 -> 0 | G12: =C12*N12 -> 0 | H12: =IF(B12>0,CEILING(B12/O12,1),0) -> 0 | I12: =IF(C12>0,CEILING(C12/O12,1),0) -> 0 | J12: =H12*'1_Svodka'!$B$13 -> 0 | K12: =I12*'1_Svodka'!$B$13 -> 0 | L12: =IF(B12+C12=0,"",H12&" секц. слева / "&I12&" справа; "&J12&" дверей слева / "&K12&" справа") | M12: ='3_Normativy'!C12 -> 0.6 | N12: ='3_Normativy'!F12 -> 0.3 | O12: ='3_Normativy'!G12 -> 250
A13: Откормочное поголовье молодняк | B13: 0 | C13: 0 | D13: =B13*M13 -> 0 | E13: =C13*M13 -> 0 | F13: =B13*N13 -> 0 | G13: =C13*N13 -> 0 | H13: =IF(B13>0,CEILING(B13/O13,1),0) -> 0 | I13: =IF(C13>0,CEILING(C13/O13,1),0) -> 0 | J13: =H13*'1_Svodka'!$B$13 -> 0 | K13: =I13*'1_Svodka'!$B$13 -> 0 | L13: =IF(B13+C13=0,"",H13&" секц. слева / "&I13&" справа; "&J13&" дверей слева / "&K13&" справа") | M13: ='3_Normativy'!C13 -> 0.48 | N13: ='3_Normativy'!F13 -> 0.25 | O13: ='3_Normativy'!G13 -> 250
A14: Валухи | B14: 0 | C14: 0 | D14: =B14*M14 -> 0 | E14: =C14*M14 -> 0 | F14: =B14*N14 -> 0 | G14: =C14*N14 -> 0 | H14: =IF(B14>0,CEILING(B14/O14,1),0) -> 0 | I14: =IF(C14>0,CEILING(C14/O14,1),0) -> 0 | J14: =H14*'1_Svodka'!$B$13 -> 0 | K14: =I14*'1_Svodka'!$B$13 -> 0 | L14: =IF(B14+C14=0,"",H14&" секц. слева / "&I14&" справа; "&J14&" дверей слева / "&K14&" справа") | M14: ='3_Normativy'!C14 -> 0.6 | N14: ='3_Normativy'!F14 -> 0.3 | O14: ='3_Normativy'!G14 -> 250
A16: ИТОГО | B16: =SUM(B2:B14) -> 600 | C16: =SUM(C2:C14) -> 600 | D16: =SUM(D2:D14) -> 540 | E16: =SUM(E2:E14) -> 540 | F16: =SUM(F2:F14) -> 135 | G16: =SUM(G2:G14) -> 135 | H16: =SUM(H2:H14) -> 15 | I16: =SUM(I2:I14) -> 15 | ... K16: =SUM(K2:K14) -> 15
A19: Двери по строкам рассчитываются как количество секций × число дверей на секцию. На листе «1_Svodka» можно выбрать другой режим — фиксированное число дверей отдельно для левой и правой стороны. В итоговом кормовом фронте используются именно значения из выбранного режима; все двери выходят в центральный кормовой проход.
A23: Пример: 600 племенных маток, разбиты по двум сторонам+ сделана секция для откормочного молодняка справа, на странице Сводка такая компоновка не пройдет, т к фронта кормления на молодняк не хватит+можно проверить нормы кормления ив Сводке поставить 2 головы на фронт, размер стола уменьшится

Sheet 3_Normativy
A1: Группа животных | B1: Базовая площадь, м²/гол. | C1: Племенная площадь, м²/гол. | D1: Базовый фронт, м/гол. | E1: Коэф. доступа к корму | F1: Расчетный фронт, м/гол. | G1: Макс. животных в секции | H1: Основание НТП-АПК | I1: Комментарий
A2: Бараны-производители | B2: 2 | C2: =B2*(1+'1_Svodka'!$B$12) -> 2.4 | D2: 0.5 | E2: 1 | F2: =D2/E2 -> 0.5 | G2: 25 | H2: табл. 9; табл. 10; п. 4.4 | I2: Секция до 25 голов
A3: Бараны-пробники | B3: 1.8 | C3: =B3*(1+'1_Svodka'!$B$12) -> 2.16 | D3: 0.5 | E3: 1 | F3: =D3/E3 -> 0.5 | G3: 50 | H3: табл. 9; табл. 10; п. 4.4 | I3: Секция до 50 голов
A4: Матки холостые | B4: 0.7 | C4: =B4*(1+'1_Svodka'!$B$12) -> 0.84 | D4: 0.3 | E4: 1 | F4: =D4/E4 -> 0.3 | G4: 250 | H4: табл. 9; табл. 10; п. 4.4 | I4: Для маток в НТП 0,3–0,4 м/гол.; принято 0,3
A5: Матки суягные | B5: 1 | C5: =B5*(1+'1_Svodka'!$B$12) -> 1.2 | D5: 0.3 | E5: 1 | F5: =D5/E5 -> 0.3 | G5: 250 | H5: табл. 9; табл. 10; п. 4.4 | I5: Для маток в НТП 0,3–0,4 м/гол.; принято 0,3
A6: Матки подсосные с ягнятами до 10 дней | B6: 1.2 | C6: =B6*(1+'1_Svodka'!$B$12) -> 1.44 | D6: 0.3 | E6: 1 | F6: =D6/E6 -> 0.3 | G6: 120 | H6: табл. 9; табл. 10; п. 4.4 | I6: Секция до 120 голов
A7: Матки подсосные старше 10 дней, зимнее ягнение | B7: 1.2 | C7: =B7*(1+'1_Svodka'!$B$12) -> 1.44 | D7: 0.3 | E7: 1 | F7: =D7/E7 -> 0.3 | G7: 120 | H7: табл. 9; табл. 10; п. 4.4 | I7: Секция до 120 голов
A8: Матки подсосные старше 10 дней, весеннее ягнение | B8: 1 | C8: =B8*(1+'1_Svodka'!$B$12) -> 1.2 | D8: 0.3 | E8: 1 | F8: =D8/E8 -> 0.3 | G8: 120 | H8: табл. 9; табл. 10; п. 4.4 | I8: Секция до 120 голов
A9: Ремонтный молодняк | B9: 0.7 | C9: =B9*(1+'1_Svodka'!$B$12) -> 0.84 | D9: 0.3 | E9: 1 | F9: =D9/E9 -> 0.3 | G9: 250 | H9: табл. 9; табл. 10; п. 4.4 | I9: Секция до 250 голов
A10: Ягнята до 45 дней | B10: 0.3 | C10: =B10*(1+'1_Svodka'!$B$12) -> 0.36 | D10: 0.15 | E10: 1 | F10: =D10/E10 -> 0.15 | G10: 25 | H10: табл. 9; табл. 10; п. 4.4 | I10: Секция до 25 голов
A11: Ягнята старше 45 дней до 4 месяцев | B11: 0.4 | C11: =B11*(1+'1_Svodka'!$B$12) -> 0.48 | D11: 0.2 | E11: 1 | F11: =D11/E11 -> 0.2 | G11: 50 | H11: табл. 9; табл. 10; п. 4.4 | I11: Секция до 50 голов
A12: Откормочное поголовье взрослое | B12: 0.5 | C12: =B12*(1+'1_Svodka'!$B$12) -> 0.6 | D12: 0.3 | E12: =IF('1_Svodka'!$B$15="Свободный доступ (2 головы на место)",2,1) -> 1 | F12: =D12/E12 -> 0.3 | G12: 250 | H12: табл. 9; табл. 10; п. 7.3; п. 4.4 | I12: При свободном доступе — 2 овцы на 1 кормовое место
A13: Откормочное поголовье молодняк | B13: 0.4 | C13: =B13*(1+'1_Svodka'!$B$12) -> 0.48 | D13: 0.25 | E13: =IF('1_Svodka'!$B$15="Свободный доступ (2 головы на место)",2,1) -> 1 | F13: =D13/E13 -> 0.25 | G13: 250 | H13: табл. 9; табл. 10; п. 7.3; п. 4.4 | I13: При свободном доступе — 2 овцы на 1 кормовое место
A14: Валухи | B14: 0.5 | C14: =B14*(1+'1_Svodka'!$B$12) -> 0.6 | D14: 0.3 | E14: 1 | F14: =D14/E14 -> 0.3 | G14: 250 | H14: табл. 9; табл. 10 | I14: Размер секции 250 принят по аналогии с откормочным поголовьем
A17: Формулы и принятая логика
A18: Площадь здания | B18: L × (центральный проход + 2 зоны содержания + 2 технических прохода, если они включены).
A19: Площадь содержания | B19: Для каждой стороны отдельно: L × заданная ширина зоны содержания.
A20: Племенная площадь | B20: Базовая норма × (1 + надбавка для племенного поголовья).
A21: Секции | B21: Количество секций = округление вверх: поголовье / максимальное число животных в секции.
A22: Двери | B22: Количество дверей = число секций × заданное число дверей на секцию. Все двери выходят в центральный кормовой проход.
A23: Полезный фронт кормления | B23: L − суммарная ширина дверных проемов на соответствующей стороне.
A24: Свободный доступ к корму | B24: Для откормочного поголовья при выбранном свободном доступе расчетный фронт делится на 2: две овцы на одно кормовое место по п. 7.3.
A26: Нормативная основа
A27: НТП-АПК 1.10.03.001-00 «Нормы технологического проектирования овцеводческих предприятий». Использованы: п. 4.4; табл. 9 и примечания; табл. 10; п. 7.3.
A30: Электронная копия:
A31: http://files.stroyinf.ru/Data2/1/4294846/4294846504.htm
A33: Пример: Есть вопрос по "габаритам" туш при кормлении, Наталия при выборе весов говорила, что 600 в ширину может быть мало, так как тогда животные могут друг к другу встать при кормлении с учетом норм АПК?
